<?xml version="1.0" ?>
<!-- =================================================================================== -->
<!-- |    This document was autogenerated by xacro from /home/RVLuser/ferit_ur5_ws/src/ur5_configs/fmauch_universal_robot/ur_description/urdf/ur5_robotiq_ft_3f.urdf.xacro | -->
<!-- |    EDITING THIS FILE BY HAND IS NOT RECOMMENDED                                 | -->
<!-- =================================================================================== -->
<robot name="ur5_robotiq_ft_3f">
    <link name="finger_1_link_0">
        <visual>
            <origin rpy="0 0 0" xyz="0.020 0 0" />
            <geometry>
                <mesh filename="package://robotiq_3f_gripper_visualization/meshes/robotiq-3f-gripper_articulated/visual/link_0.dae" />
            </geometry>
            <material name="green">
                <color rgba="0 1 0 1" />
            </material>
        </visual>
        <collision>
            <origin rpy="0 3.1416 -1.57" xyz="-0.0455 0.0414 0.036" />
            <geometry>
                <mesh filename="package://robotiq_3f_gripper_visualization/meshes/robotiq-3f-gripper_articulated/collision/link_0.STL" />
            </geometry>
            <material name="yellow">
                <color rgba="0 1 1 1" />
            </material>
        </collision>
        <inertial>
            <origin rpy="0 0 0" xyz="0 0 0" />
            <mass value="0.05" />
            <inertia ixx="0.01" ixy="-0.00002" ixz="0.00001" iyy="0.0008" iyz="0" izz="0.001" />
        </inertial>
    </link>
    <link name="finger_1_link_1">
        <visual>
            <origin rpy="0 0 -0.52" xyz="0.050 -.028 0" />
            <geometry>
                <mesh filename="package://robotiq_3f_gripper_visualization/meshes/robotiq-3f-gripper_articulated/visual/link_1.dae" />
            </geometry>
            <material name="green" />
        </visual>
        <collision>
            <origin rpy="0 0 -0.52" xyz="0.050 -.028 0" />
            <geometry>
                <mesh filename="package://robotiq_3f_gripper_visualization/meshes/robotiq-3f-gripper_articulated/collision/link_1.STL" />
            </geometry>
            <material name="yellow" />
        </collision>
        <inertial>
            <origin rpy="0 0 0" xyz="0 0 0" />
            <mass value="0.15" />
            <inertia ixx="0.001859" ixy="-0.000376" ixz="0.000028" iyy="0.012756" iyz="0" izz="0.0024" />
        </inertial>
    </link>
    <link name="finger_1_link_2">
        <!--
			NOTE: This link has an offset in the z-direction based on the models that were
			used to generate grap-it poses.  With the offset below the model appears visually
			correct, but it is suspect.
			-->
        <visual>
            <origin rpy="0 0 0" xyz="0.039 0 0.0075" />
            <geometry>
                <mesh filename="package://robotiq_3f_gripper_visualization/meshes/robotiq-3f-gripper_articulated/visual/link_2.dae" />
            </geometry>
            <material name="green" />
        </visual>
        <collision>
            <origin rpy="0 0 0" xyz="0.039 0 0.0075" />
            <geometry>
                <mesh filename="package://robotiq_3f_gripper_visualization/meshes/robotiq-3f-gripper_articulated/collision/link_2.STL" />
            </geometry>
            <material name="yellow" />
        </collision>
        <inertial>
            <origin rpy="0 0 0" xyz="0 0 0" />
            <mass value="0.15" />
            <inertia ixx="0.001859" ixy="-0.000376" ixz="0.000028" iyy="0.012756" iyz="0" izz="0.0024" />
        </inertial>
    </link>
    <link name="finger_1_link_3">
        <visual>
            <origin rpy="0 0 0.52" xyz="0 0 0" />
            <geometry>
                <mesh filename="package://robotiq_3f_gripper_visualization/meshes/robotiq-3f-gripper_articulated/visual/link_3.dae" />
            </geometry>
            <material name="green" />
        </visual>
        <collision>
            <origin rpy="0 0 0.52" xyz="0 0 0" />
            <geometry>
                <mesh filename="package://robotiq_3f_gripper_visualization/meshes/robotiq-3f-gripper_articulated/collision/link_3.STL" />
            </geometry>
            <material name="yellow" />
        </collision>
        <inertial>
            <origin rpy="0 0 0" xyz="0 0 0" />
            <mass value="0.05" />
            <inertia ixx="0.001239" ixy="-0.000251" ixz="0.000019" iyy="0.00085" iyz="0" izz="0.001632" />
        </inertial>
    </link>
    <joint name="finger_1_joint_1" type="fixed">
        <parent link="finger_1_link_0" />
        <child link="finger_1_link_1" />
        <axis xyz="0 0 1" />
        <origin rpy="0 -0.19 0.065" xyz="0.020 0 0" />
        <limit effort="100" lower="0" upper="3.1416" velocity="100" />
    </joint>
    <joint name="finger_1_joint_2" type="fixed">
        <parent link="finger_1_link_1" />
        <child link="finger_1_link_2" />
        <axis xyz="0 0 1" />
        <origin rpy="0 0 -0.52" xyz="0.050 -.028 0" />
        <limit effort="100" lower="0" upper="3.1416" velocity="100" />
    </joint>
    <joint name="finger_1_joint_3" type="fixed">
        <parent link="finger_1_link_2" />
        <child link="finger_1_link_3" />
        <axis xyz="0 0 1" />
        <origin rpy="0 0 0" xyz="0.039 0 0" />
        <limit effort="100" lower="0" upper="3.1416" velocity="100" />
    </joint>
    <link name="finger_2_link_0">
        <visual>
            <origin rpy="0 0 0" xyz="0.020 0 0" />
            <geometry>
                <mesh filename="package://robotiq_3f_gripper_visualization/meshes/robotiq-3f-gripper_articulated/visual/link_0.dae" />
            </geometry>
            <material name="green">
                <color rgba="0 1 0 1" />
            </material>
        </visual>
        <collision>
            <origin rpy="0 3.1416 -1.57" xyz="-0.0455 0.0414 0.036" />
            <geometry>
                <mesh filename="package://robotiq_3f_gripper_visualization/meshes/robotiq-3f-gripper_articulated/collision/link_0.STL" />
            </geometry>
            <material name="yellow">
                <color rgba="0 1 1 1" />
            </material>
        </collision>
        <inertial>
            <origin rpy="0 0 0" xyz="0 0 0" />
            <mass value="0.05" />
            <inertia ixx="0.01" ixy="-0.00002" ixz="0.00001" iyy="0.0008" iyz="0" izz="0.001" />
        </inertial>
    </link>
    <link name="finger_2_link_1">
        <visual>
            <origin rpy="0 0 -0.52" xyz="0.050 -.028 0" />
            <geometry>
                <mesh filename="package://robotiq_3f_gripper_visualization/meshes/robotiq-3f-gripper_articulated/visual/link_1.dae" />
            </geometry>
            <material name="green" />
        </visual>
        <collision>
            <origin rpy="0 0 -0.52" xyz="0.050 -.028 0" />
            <geometry>
                <mesh filename="package://robotiq_3f_gripper_visualization/meshes/robotiq-3f-gripper_articulated/collision/link_1.STL" />
            </geometry>
            <material name="yellow" />
        </collision>
        <inertial>
            <origin rpy="0 0 0" xyz="0 0 0" />
            <mass value="0.15" />
            <inertia ixx="0.001859" ixy="-0.000376" ixz="0.000028" iyy="0.012756" iyz="0" izz="0.0024" />
        </inertial>
    </link>
    <link name="finger_2_link_2">
        <!--
			NOTE: This link has an offset in the z-direction based on the models that were
			used to generate grap-it poses.  With the offset below the model appears visually
			correct, but it is suspect.
			-->
        <visual>
            <origin rpy="0 0 0" xyz="0.039 0 0.0075" />
            <geometry>
                <mesh filename="package://robotiq_3f_gripper_visualization/meshes/robotiq-3f-gripper_articulated/visual/link_2.dae" />
            </geometry>
            <material name="green" />
        </visual>
        <collision>
            <origin rpy="0 0 0" xyz="0.039 0 0.0075" />
            <geometry>
                <mesh filename="package://robotiq_3f_gripper_visualization/meshes/robotiq-3f-gripper_articulated/collision/link_2.STL" />
            </geometry>
            <material name="yellow" />
        </collision>
        <inertial>
            <origin rpy="0 0 0" xyz="0 0 0" />
            <mass value="0.15" />
            <inertia ixx="0.001859" ixy="-0.000376" ixz="0.000028" iyy="0.012756" iyz="0" izz="0.0024" />
        </inertial>
    </link>
    <link name="finger_2_link_3">
        <visual>
            <origin rpy="0 0 0.52" xyz="0 0 0" />
            <geometry>
                <mesh filename="package://robotiq_3f_gripper_visualization/meshes/robotiq-3f-gripper_articulated/visual/link_3.dae" />
            </geometry>
            <material name="green" />
        </visual>
        <collision>
            <origin rpy="0 0 0.52" xyz="0 0 0" />
            <geometry>
                <mesh filename="package://robotiq_3f_gripper_visualization/meshes/robotiq-3f-gripper_articulated/collision/link_3.STL" />
            </geometry>
            <material name="yellow" />
        </collision>
        <inertial>
            <origin rpy="0 0 0" xyz="0 0 0" />
            <mass value="0.05" />
            <inertia ixx="0.001239" ixy="-0.000251" ixz="0.000019" iyy="0.00085" iyz="0" izz="0.001632" />
        </inertial>
    </link>
    <joint name="finger_2_joint_1" type="fixed">
        <parent link="finger_2_link_0" />
        <child link="finger_2_link_1" />
        <axis xyz="0 0 1" />
        <origin rpy="0 0.19 0.065" xyz="0.020 0 0" />
        <limit effort="100" lower="0" upper="3.1416" velocity="100" />
    </joint>
    <joint name="finger_2_joint_2" type="fixed">
        <parent link="finger_2_link_1" />
        <child link="finger_2_link_2" />
        <axis xyz="0 0 1" />
        <origin rpy="0 0 -0.52" xyz="0.050 -.028 0" />
        <limit effort="100" lower="0" upper="3.1416" velocity="100" />
    </joint>
    <joint name="finger_2_joint_3" type="fixed">
        <parent link="finger_2_link_2" />
        <child link="finger_2_link_3" />
        <axis xyz="0 0 1" />
        <origin rpy="0 0 0" xyz="0.039 0 0" />
        <limit effort="100" lower="0" upper="3.1416" velocity="100" />
    </joint>
    <link name="finger_middle_link_0">
        <visual>
            <origin rpy="0 0 0" xyz="0.020 0 0" />
            <geometry>
                <mesh filename="package://robotiq_3f_gripper_visualization/meshes/robotiq-3f-gripper_articulated/visual/link_0.dae" />
            </geometry>
            <material name="green">
                <color rgba="0 1 0 1" />
            </material>
        </visual>
        <collision>
            <origin rpy="0 3.1416 -1.57" xyz="-0.0455 0.0414 0.036" />
            <geometry>
                <mesh filename="package://robotiq_3f_gripper_visualization/meshes/robotiq-3f-gripper_articulated/collision/link_0.STL" />
            </geometry>
            <material name="yellow">
                <color rgba="0 1 1 1" />
            </material>
        </collision>
        <inertial>
            <origin rpy="0 0 0" xyz="0 0 0" />
            <mass value="0.05" />
            <inertia ixx="0.01" ixy="-0.00002" ixz="0.00001" iyy="0.0008" iyz="0" izz="0.001" />
        </inertial>
    </link>
    <link name="finger_middle_link_1">
        <visual>
            <origin rpy="0 0 -0.52" xyz="0.050 -.028 0" />
            <geometry>
                <mesh filename="package://robotiq_3f_gripper_visualization/meshes/robotiq-3f-gripper_articulated/visual/link_1.dae" />
            </geometry>
            <material name="green" />
        </visual>
        <collision>
            <origin rpy="0 0 -0.52" xyz="0.050 -.028 0" />
            <geometry>
                <mesh filename="package://robotiq_3f_gripper_visualization/meshes/robotiq-3f-gripper_articulated/collision/link_1.STL" />
            </geometry>
            <material name="yellow" />
        </collision>
        <inertial>
            <origin rpy="0 0 0" xyz="0 0 0" />
            <mass value="0.15" />
            <inertia ixx="0.001859" ixy="-0.000376" ixz="0.000028" iyy="0.012756" iyz="0" izz="0.0024" />
        </inertial>
    </link>
    <link name="finger_middle_link_2">
        <!--
			NOTE: This link has an offset in the z-direction based on the models that were
			used to generate grap-it poses.  With the offset below the model appears visually
			correct, but it is suspect.
			-->
        <visual>
            <origin rpy="0 0 0" xyz="0.039 0 0.0075" />
            <geometry>
                <mesh filename="package://robotiq_3f_gripper_visualization/meshes/robotiq-3f-gripper_articulated/visual/link_2.dae" />
            </geometry>
            <material name="green" />
        </visual>
        <collision>
            <origin rpy="0 0 0" xyz="0.039 0 0.0075" />
            <geometry>
                <mesh filename="package://robotiq_3f_gripper_visualization/meshes/robotiq-3f-gripper_articulated/collision/link_2.STL" />
            </geometry>
            <material name="yellow" />
        </collision>
        <inertial>
            <origin rpy="0 0 0" xyz="0 0 0" />
            <mass value="0.15" />
            <inertia ixx="0.001859" ixy="-0.000376" ixz="0.000028" iyy="0.012756" iyz="0" izz="0.0024" />
        </inertial>
    </link>
    <link name="finger_middle_link_3">
        <visual>
            <origin rpy="0 0 0.52" xyz="0 0 0" />
            <geometry>
                <mesh filename="package://robotiq_3f_gripper_visualization/meshes/robotiq-3f-gripper_articulated/visual/link_3.dae" />
            </geometry>
            <material name="green" />
        </visual>
        <collision>
            <origin rpy="0 0 0.52" xyz="0 0 0" />
            <geometry>
                <mesh filename="package://robotiq_3f_gripper_visualization/meshes/robotiq-3f-gripper_articulated/collision/link_3.STL" />
            </geometry>
            <material name="yellow" />
        </collision>
        <inertial>
            <origin rpy="0 0 0" xyz="0 0 0" />
            <mass value="0.05" />
            <inertia ixx="0.001239" ixy="-0.000251" ixz="0.000019" iyy="0.00085" iyz="0" izz="0.001632" />
        </inertial>
    </link>
    <joint name="finger_middle_joint_1" type="fixed">
        <parent link="finger_middle_link_0" />
        <child link="finger_middle_link_1" />
        <axis xyz="0 0 1" />
        <origin rpy="0 0 0" xyz="0.020 0 0" />
        <limit effort="100" lower="0" upper="3.1416" velocity="100" />
    </joint>
    <joint name="finger_middle_joint_2" type="fixed">
        <parent link="finger_middle_link_1" />
        <child link="finger_middle_link_2" />
        <axis xyz="0 0 1" />
        <origin rpy="0 0 -0.52" xyz="0.050 -.028 0" />
        <limit effort="100" lower="0" upper="3.1416" velocity="100" />
    </joint>
    <joint name="finger_middle_joint_3" type="fixed">
        <parent link="finger_middle_link_2" />
        <child link="finger_middle_link_3" />
        <axis xyz="0 0 1" />
        <origin rpy="0 0 0" xyz="0.039 0 0" />
        <limit effort="100" lower="0" upper="3.1416" velocity="100" />
    </joint>
    <link name="palm">
        <visual>
            <geometry>
                <mesh filename="package://robotiq_3f_gripper_visualization/meshes/robotiq-3f-gripper_articulated/visual/palm.dae" />
            </geometry>
            <material name="green">
                <color rgba="0 1 0 1" />
            </material>
        </visual>
        <collision>
            <geometry>
                <mesh filename="package://robotiq_3f_gripper_visualization/meshes/robotiq-3f-gripper_articulated/collision/palm.STL" />
            </geometry>
            <material name="yellow">
                <color rgba="0 1 1 1" />
            </material>
        </collision>
        <inertial>
            <mass value="0.1" />
            <origin xyz="0 0 0" rpy="0 0 0" />
            <inertia ixx="0.03" iyy="0.03" izz="0.03" ixy="0.0" ixz="0.0" iyz="0.0" />
        </inertial>
    </link>
    <inertial>
        <origin rpy="0 0 0" xyz="0 0 0" />
        <mass value="1.3" />
        <inertia ixx="0.006012" ixy="0.000079" ixz="-0.00024" iyy="0.012892" iyz="0" izz="0.002435" />
    </inertial>
    <joint name="palm_finger_1_joint" type="fixed">
        <parent link="palm" />
        <child link="finger_1_link_0" />
        <axis xyz="0 1 0" />
        <origin rpy="0 3.1416 -1.57" xyz="-0.0455 0.0214 0.036" />
        <limit effort="100" lower="-0.16" upper="0.25" velocity="100" />
    </joint>
    <joint name="palm_finger_2_joint" type="fixed">
        <parent link="palm" />
        <child link="finger_2_link_0" />
        <axis xyz="0 1 0" />
        <origin rpy="0 3.1416 -1.57" xyz="-0.0455 0.0214 -0.036" />
        <limit effort="100" lower="-0.25" upper="0.16" velocity="100" />
    </joint>
    <joint name="palm_finger_middle_joint" type="fixed">
        <parent link="palm" />
        <child link="finger_middle_link_0" />
        <axis xyz="0 0 1" />
        <origin rpy="0 0 1.57" xyz="0.0455 0.0214 0" />
    </joint>
    <!--
        <include filename="$(find robotiq_3f_gripper_visualization)/cfg/robotiq-3f-gripper_finger_articulated_macro.xacro" />
        <xacro:robotiq-3f-gripper_finger_articulated prefix=""/>
-->
    <!--
    Base UR robot series xacro macro.

    NOTE: this is NOT a URDF. It cannot directly be loaded by consumers
    expecting a flattened '.urdf' file. See the top-level '.xacro' for that
    (but note: that .xacro must still be processed by the xacro command).

    For use in '.launch' files: use one of the 'load_urX.launch' convenience
    launch files.

    This file models the base kinematic chain of a UR robot, which then gets
    parameterised by various configuration files to convert it into a UR3(e),
    UR5(e), UR10(e) or UR16e.

    NOTE: the default kinematic parameters (ie: link lengths, frame locations,
    offets, etc) do not correspond to any particular robot. They are defaults
    only. There WILL be non-zero offsets between the Forward Kinematics results
    in TF (ie: robot_state_publisher) and the values reported by the Teach
    Pendant.

    For accurate (and robot-specific) transforms, the 'kinematics_parameters_file'
    parameter MUST point to a .yaml file containing the appropriate values for
    the targetted robot.

    If using the UniversalRobots/Universal_Robots_ROS_Driver, follow the steps
    described in the readme of that repository to extract the kinematic
    calibration from the controller and generate the required .yaml file.

    Main author of the migration to yaml configs: Ludovic Delval.

    Contributors to previous versions (in no particular order):

     - Felix Messmer
     - Kelsey Hawkins
     - Wim Meeussen
     - Shaun Edwards
     - Nadia Hammoudeh Garcia
     - Dave Hershberger
     - G. vd. Hoorn
     - Philip Long
     - Dave Coleman
     - Miguel Prada
     - Mathias Luedtke
     - Marcel Schnirring
     - Felix von Drigalski
     - Felix Exner
     - Jimmy Da Silva
     - Ajit Krisshna N L
     - Muhammad Asif Rana
  -->
    <!--
    NOTE: the macro defined in this file is NOT part of the public API of this
          package. Users CANNOT rely on this file being available, or stored in
          this location. Nor can they rely on the existence of the macro.
  -->
    <transmission name="shoulder_pan_trans">
        <type>transmission_interface/SimpleTransmission</type>
        <joint name="shoulder_pan_joint">
            <hardwareInterface>hardware_interface/PositionJointInterface</hardwareInterface>
        </joint>
        <actuator name="shoulder_pan_motor">
            <mechanicalReduction>1</mechanicalReduction>
            <hardwareInterface>hardware_interface/EffortJointInterface</hardwareInterface>
        </actuator>
    </transmission>
    <transmission name="shoulder_lift_trans">
        <type>transmission_interface/SimpleTransmission</type>
        <joint name="shoulder_lift_joint">
            <hardwareInterface>hardware_interface/PositionJointInterface</hardwareInterface>
        </joint>
        <actuator name="shoulder_lift_motor">
            <mechanicalReduction>1</mechanicalReduction>
            <hardwareInterface>hardware_interface/EffortJointInterface</hardwareInterface>
        </actuator>
    </transmission>
    <transmission name="elbow_trans">
        <type>transmission_interface/SimpleTransmission</type>
        <joint name="elbow_joint">
            <hardwareInterface>hardware_interface/PositionJointInterface</hardwareInterface>
        </joint>
        <actuator name="elbow_motor">
            <mechanicalReduction>1</mechanicalReduction>
            <hardwareInterface>hardware_interface/EffortJointInterface</hardwareInterface>
        </actuator>
    </transmission>
    <transmission name="wrist_1_trans">
        <type>transmission_interface/SimpleTransmission</type>
        <joint name="wrist_1_joint">
            <hardwareInterface>hardware_interface/PositionJointInterface</hardwareInterface>
        </joint>
        <actuator name="wrist_1_motor">
            <mechanicalReduction>1</mechanicalReduction>
            <hardwareInterface>hardware_interface/EffortJointInterface</hardwareInterface>
        </actuator>
    </transmission>
    <transmission name="wrist_2_trans">
        <type>transmission_interface/SimpleTransmission</type>
        <joint name="wrist_2_joint">
            <hardwareInterface>hardware_interface/PositionJointInterface</hardwareInterface>
        </joint>
        <actuator name="wrist_2_motor">
            <mechanicalReduction>1</mechanicalReduction>
            <hardwareInterface>hardware_interface/EffortJointInterface</hardwareInterface>
        </actuator>
    </transmission>
    <transmission name="wrist_3_trans">
        <type>transmission_interface/SimpleTransmission</type>
        <joint name="wrist_3_joint">
            <hardwareInterface>hardware_interface/PositionJointInterface</hardwareInterface>
        </joint>
        <actuator name="wrist_3_motor">
            <mechanicalReduction>1</mechanicalReduction>
            <hardwareInterface>hardware_interface/EffortJointInterface</hardwareInterface>
        </actuator>
    </transmission>
    <!-- links: main serial chain -->
    <link name="base_link" />
    <link name="base_link_inertia">
        <visual>
            <origin rpy="0 0 3.141592653589793" xyz="0 0 0" />
            <geometry>
                <mesh filename="package://ur_description/meshes/ur5/visual/base.dae" />
            </geometry>
            <material name="LightGrey">
                <color rgba="0.7 0.7 0.7 1.0" />
            </material>
        </visual>
        <collision>
            <origin rpy="0 0 3.141592653589793" xyz="0 0 0" />
            <geometry>
                <mesh filename="package://ur_description/meshes/ur5/collision/base.stl" />
            </geometry>
        </collision>
        <inertial>
            <mass value="4.0" />
            <origin rpy="0 0 0" xyz="0 0 0" />
            <inertia ixx="0.00443333156" ixy="0.0" ixz="0.0" iyy="0.00443333156" iyz="0.0" izz="0.0072" />
        </inertial>
    </link>
    <link name="shoulder_link">
        <visual>
            <origin rpy="0 0 3.141592653589793" xyz="0 0 0" />
            <geometry>
                <mesh filename="package://ur_description/meshes/ur5/visual/shoulder.dae" />
            </geometry>
            <material name="LightGrey">
                <color rgba="0.7 0.7 0.7 1.0" />
            </material>
        </visual>
        <collision>
            <origin rpy="0 0 3.141592653589793" xyz="0 0 0" />
            <geometry>
                <mesh filename="package://ur_description/meshes/ur5/collision/shoulder.stl" />
            </geometry>
        </collision>
        <inertial>
            <mass value="3.7" />
            <origin rpy="0 0 0" xyz="0 0 0" />
            <inertia ixx="0.014972352344389999" ixy="0.0" ixz="0.0" iyy="0.014972352344389999" iyz="0.0" izz="0.01040625" />
        </inertial>
    </link>
    <link name="upper_arm_link">
        <visual>
            <origin rpy="1.5707963267948966 0 -1.5707963267948966" xyz="0 0 0.13585" />
            <geometry>
                <mesh filename="package://ur_description/meshes/ur5/visual/upperarm.dae" />
            </geometry>
            <material name="LightGrey">
                <color rgba="0.7 0.7 0.7 1.0" />
            </material>
        </visual>
        <collision>
            <origin rpy="1.5707963267948966 0 -1.5707963267948966" xyz="0 0 0.13585" />
            <geometry>
                <mesh filename="package://ur_description/meshes/ur5/collision/upperarm.stl" />
            </geometry>
        </collision>
        <inertial>
            <mass value="8.393" />
            <origin rpy="0 1.5707963267948966 0" xyz="-0.2125 0.0 0.136" />
            <inertia ixx="0.1338857818623325" ixy="0.0" ixz="0.0" iyy="0.1338857818623325" iyz="0.0" izz="0.0151074" />
        </inertial>
    </link>
    <link name="forearm_link">
        <visual>
            <origin rpy="1.5707963267948966 0 -1.5707963267948966" xyz="0 0 0.0165" />
            <geometry>
                <mesh filename="package://ur_description/meshes/ur5/visual/forearm.dae" />
            </geometry>
            <material name="LightGrey">
                <color rgba="0.7 0.7 0.7 1.0" />
            </material>
        </visual>
        <collision>
            <origin rpy="1.5707963267948966 0 -1.5707963267948966" xyz="0 0 0.0165" />
            <geometry>
                <mesh filename="package://ur_description/meshes/ur5/collision/forearm.stl" />
            </geometry>
        </collision>
        <inertial>
            <mass value="2.275" />
            <origin rpy="0 1.5707963267948966 0" xyz="-0.196125 0.0 0.0165" />
            <inertia ixx="0.03121679102890359" ixy="0.0" ixz="0.0" iyy="0.03121679102890359" iyz="0.0" izz="0.004095" />
        </inertial>
    </link>
    <link name="wrist_1_link">
        <visual>
            <!-- TODO: Move this to a parameter -->
            <origin rpy="1.5707963267948966 0 0" xyz="0 0 -0.093" />
            <geometry>
                <mesh filename="package://ur_description/meshes/ur5/visual/wrist1.dae" />
            </geometry>
            <material name="LightGrey">
                <color rgba="0.7 0.7 0.7 1.0" />
            </material>
        </visual>
        <collision>
            <origin rpy="1.5707963267948966 0 0" xyz="0 0 -0.093" />
            <geometry>
                <mesh filename="package://ur_description/meshes/ur5/collision/wrist1.stl" />
            </geometry>
        </collision>
        <inertial>
            <mass value="1.219" />
            <origin rpy="0 0 0" xyz="0 0 0" />
            <inertia ixx="0.0020138887777775" ixy="0.0" ixz="0.0" iyy="0.0020138887777775" iyz="0.0" izz="0.0021942" />
        </inertial>
    </link>
    <link name="wrist_2_link">
        <visual>
            <origin rpy="0 0 0" xyz="0 0 -0.095" />
            <geometry>
                <mesh filename="package://ur_description/meshes/ur5/visual/wrist2.dae" />
            </geometry>
            <material name="LightGrey">
                <color rgba="0.7 0.7 0.7 1.0" />
            </material>
        </visual>
        <collision>
            <origin rpy="0 0 0" xyz="0 0 -0.095" />
            <geometry>
                <mesh filename="package://ur_description/meshes/ur5/collision/wrist2.stl" />
            </geometry>
        </collision>
        <inertial>
            <mass value="1.219" />
            <origin rpy="0 0 0" xyz="0 0 0" />
            <inertia ixx="0.0018310388509175" ixy="0.0" ixz="0.0" iyy="0.0018310388509175" iyz="0.0" izz="0.0021942" />
        </inertial>
    </link>
    <link name="wrist_3_link">
        <visual>
            <origin rpy="1.5707963267948966 0 0" xyz="0 0 -0.0818" />
            <geometry>
                <mesh filename="package://ur_description/meshes/ur5/visual/wrist3.dae" />
            </geometry>
            <material name="LightGrey">
                <color rgba="0.7 0.7 0.7 1.0" />
            </material>
        </visual>
        <collision>
            <origin rpy="1.5707963267948966 0 0" xyz="0 0 -0.0818" />
            <geometry>
                <mesh filename="package://ur_description/meshes/ur5/collision/wrist3.stl" />
            </geometry>
        </collision>
        <inertial>
            <mass value="0.1879" />
            <origin rpy="0 0 0" xyz="0.0 0.0 -0.01525" />
            <inertia ixx="8.062472608343e-05" ixy="0.0" ixz="0.0" iyy="8.062472608343e-05" iyz="0.0" izz="0.0001321171875" />
        </inertial>
    </link>
    <!-- joints: main serial chain -->
    <joint name="base_link-base_link_inertia" type="fixed">
        <parent link="base_link" />
        <child link="base_link_inertia" />
        <!-- 'base_link' is REP-103 aligned (so X+ forward), while the internal
           frames of the robot/controller have X+ pointing backwards.
           Use the joint between 'base_link' and 'base_link_inertia' (a dummy
           link/frame) to introduce the necessary rotation over Z (of pi rad).
      -->
        <origin rpy="0 0 3.141592653589793" xyz="0 0 0" />
    </joint>
    <joint name="shoulder_pan_joint" type="revolute">
        <parent link="base_link_inertia" />
        <child link="shoulder_link" />
        <origin rpy="0 0 0" xyz="0 0 0.089159" />
        <axis xyz="0 0 1" />
        <limit effort="150.0" lower="-6.283185307179586" upper="6.283185307179586" velocity="3.141592653589793" />
        <dynamics damping="0" friction="0" />
    </joint>
    <joint name="shoulder_lift_joint" type="revolute">
        <parent link="shoulder_link" />
        <child link="upper_arm_link" />
        <origin rpy="1.570796327 0 0" xyz="0 0 0" />
        <axis xyz="0 0 1" />
        <limit effort="150.0" lower="-6.283185307179586" upper="6.283185307179586" velocity="3.141592653589793" />
        <dynamics damping="0" friction="0" />
    </joint>
    <joint name="elbow_joint" type="revolute">
        <parent link="upper_arm_link" />
        <child link="forearm_link" />
        <origin rpy="0 0 0" xyz="-0.425 0 0" />
        <axis xyz="0 0 1" />
        <limit effort="150.0" lower="-3.141592653589793" upper="3.141592653589793" velocity="3.141592653589793" />
        <dynamics damping="0" friction="0" />
    </joint>
    <joint name="wrist_1_joint" type="revolute">
        <parent link="forearm_link" />
        <child link="wrist_1_link" />
        <origin rpy="0 0 0" xyz="-0.39225 0 0.10915" />
        <axis xyz="0 0 1" />
        <limit effort="28.0" lower="-6.283185307179586" upper="6.283185307179586" velocity="3.141592653589793" />
        <dynamics damping="0" friction="0" />
    </joint>
    <joint name="wrist_2_joint" type="revolute">
        <parent link="wrist_1_link" />
        <child link="wrist_2_link" />
        <origin rpy="1.570796327 0 0" xyz="0 -0.09465 -1.941303950897609e-11" />
        <axis xyz="0 0 1" />
        <limit effort="28.0" lower="-6.283185307179586" upper="6.283185307179586" velocity="3.141592653589793" />
        <dynamics damping="0" friction="0" />
    </joint>
    <joint name="wrist_3_joint" type="revolute">
        <parent link="wrist_2_link" />
        <child link="wrist_3_link" />
        <origin rpy="1.570796326589793 3.141592653589793 3.141592653589793" xyz="0 0.0823 -1.688001216681175e-11" />
        <axis xyz="0 0 1" />
        <limit effort="28.0" lower="-6.283185307179586" upper="6.283185307179586" velocity="3.141592653589793" />
        <dynamics damping="0" friction="0" />
    </joint>
    <!-- ROS-Industrial 'base' frame: base_link to UR 'Base' Coordinates transform -->
    <link name="base" />
    <joint name="base_link-base_fixed_joint" type="fixed">
        <!-- Note the rotation over Z of pi radians: as base_link is REP-103
           aligned (ie: has X+ forward, Y+ left and Z+ up), this is needed
           to correctly align 'base' with the 'Base' coordinate system of
           the UR controller.
      -->
        <origin rpy="0 0 3.141592653589793" xyz="0 0 0" />
        <parent link="base_link" />
        <child link="base" />
    </joint>
    <!-- ROS-Industrial 'flange' frame: attachment point for EEF models -->
    <link name="flange" />
    <joint name="wrist_3-flange" type="fixed">
        <parent link="wrist_3_link" />
        <child link="flange" />
        <origin rpy="0 -1.5707963267948966 -1.5707963267948966" xyz="0 0 0" />
    </joint>
    <!-- ROS-Industrial 'tool0' frame: all-zeros tool frame -->
    <link name="tool0" />
    <joint name="flange-tool0" type="fixed">
        <!-- default toolframe: X+ left, Y+ up, Z+ front -->
        <origin rpy="1.5707963267948966 0 1.5707963267948966" xyz="0 0 0" />
        <parent link="flange" />
        <child link="tool0" />
    </joint>
    <!-- mount the fts to the robot -->
    <joint name="ft300_fix" type="fixed">
        <origin rpy="0 0 0" xyz="0 0 -0.004" />
        <parent link="tool0" />
        <child link="ft300_mounting_plate" />
    </joint>
    <!-- Link representing the FT300 force-torque sensor -->
    <link name="ft300_sensor">
        <inertial>
            <origin rpy="0 0 0" xyz="0 0 -0.017" />
            <mass value="0.300" />
            <inertia ixx="0.000262" ixy="0" ixz="1e-06" iyx="0" iyy="0.000265" iyz="1e-06" izx="-1e-06" izy="1e-06" izz="0.000219" />
        </inertial>
        <visual>
            <origin rpy="0 0 0" xyz="0 0 0" />
            <geometry>
                <mesh filename="package://robotiq_ft_sensor/meshes/visual/robotiq_ft300.STL" />
            </geometry>
            <material name="Robotiq-Black">
                <color rgba="0.2 0.2 0.2 1.0" />
            </material>
        </visual>
        <collision>
            <origin rpy="0 0 0" xyz="0 0 0" />
            <geometry>
                <mesh filename="package://robotiq_ft_sensor/meshes/collision/robotiq_ft300.STL" />
            </geometry>
        </collision>
    </link>
    <!-- Link representing the FT300 mounting plate -->
    <link name="ft300_mounting_plate">
        <visual>
            <origin rpy="0 0 0" xyz="0 0 0" />
            <geometry>
                <mesh filename="package://robotiq_ft_sensor/meshes/visual/mountings/robotiq_ft300-G-062-COUPLING_G-50-4M6-1D6_20181119.STL" />
            </geometry>
            <material name="Robotiq-Grey">
                <color rgba="0.4 0.4 0.4 1.0" />
            </material>
        </visual>
        <collision>
            <origin rpy="0 0 0" xyz="0 0 0" />
            <geometry>
                <mesh filename="package://robotiq_ft_sensor/meshes/collision/mountings/robotiq_ft300-G-062-COUPLING_G-50-4M6-1D6_20181119.STL" />
            </geometry>
        </collision>
        <inertial>
            <mass value="0.1" />
            <origin xyz="0 0 0" rpy="0 0 0" />
            <inertia ixx="0.03" iyy="0.03" izz="0.03" ixy="0.0" ixz="0.0" iyz="0.0" />
        </inertial>
    </link>
    <!-- Connect force sensor with mounting/coupling plate -->
    <joint name="ft300_mounting_plate" type="fixed">
        <origin rpy="0 3.141592653589793 0" xyz="0 0 0.0415" />
        <parent link="ft300_mounting_plate" />
        <child link="ft300_sensor" />
    </joint>
    <!-- FORCE REFERENCE FRAME _______________________________________________________________________________
            As specified in the documentation:
            - The Z axis passes through the center of the depression with positive direction in the tool direction.
            - The X axis traces a symmetric line centered on the connector; the positive direction
                points the opposite way away from the connector.
            - The Y axis uses the right hand thumb rule according to X-Z. -->
    <joint name="measurment_joint" type="fixed">
        <origin rpy="0 3.141592653589793 -1.5707963267948966" xyz="0 0 0" />
        <parent link="ft300_sensor" />
        <child link="robotiq_ft_frame_id" />
    </joint>
    <link name="robotiq_ft_frame_id" />
    <link name="gripper_coupler">
        <visual>
            <origin rpy="0 0 0" xyz="0 0 0" />
            <geometry>
                <cylinder length="0.013" radius="0.04" />
            </geometry>
            <material name="Robotiq-Grey">
                <color rgba="0.4 0.4 0.4 1.0" />
            </material>
        </visual>
        <collision>
            <origin rpy="0 0 0" xyz="0 0 0" />
            <geometry>
                <cylinder length="0.013" radius="0.04" />
            </geometry>
        </collision>
        <inertial>
            <mass value="0.1" />
            <origin xyz="0 0 0" rpy="0 0 0" />
            <inertia ixx="0.03" iyy="0.03" izz="0.03" ixy="0.0" ixz="0.0" iyz="0.0" />
        </inertial>
    </link>
    <joint name="ft_sensor_gripper_coupler_joint" type="fixed">
        <!-- <origin xyz="0 0 0.0535" rpy="${-pi/2.0} ${-pi} ${-pi/4.0}" /> -->
        <!-- <origin xyz="0 0 0.0065" rpy="0 0 0" /> -->
        <origin rpy="3.141592653589793 0 0" xyz="0 0 -0.0065" />
        <parent link="ft300_sensor" />
        <child link="gripper_coupler" />
    </joint>
    <joint name="gripper_coupler_robotiq_3f_joint" type="fixed">
        <origin rpy="1.5707963267948966 0 -0.7853981633974483" xyz="0 0 0.06" />
        <parent link="gripper_coupler" />
        <child link="palm" />
    </joint>
    <link name="world" />
    <joint name="virtual_joint" type="fixed">
        <parent link="world" />
        <child link="base_link" />
        <origin rpy="0.0 0.0 0.0" xyz="0.0 0.0 0.0" />
    </joint>
    <!-- Load gazebo_ros_control -->
    <!-- <xacro:include filename="$(find ur5_description)/urdf/common.gazebo.xacro" /> -->
    <!-- <gazebo>
        <plugin name="gazebo_ros_control">
            <robotNamespace>/</robotNamespace>
        </plugin>
    </gazebo> -->
    <gazebo>
        <plugin filename="libgazebo_ros_control.so" name="ros_control" />
    </gazebo>


    <!-- Gazebo colors -->
    <gazebo reference="ft300_sensor">
        <material>Gazebo/Black</material>
    </gazebo>
    <gazebo reference="ft300_mounting_plate">
        <material>Gazebo/Black</material>
    </gazebo>
    <gazebo reference="gripper_coupler">
        <material>Gazebo/Grey</material>
    </gazebo>
</robot>

