<?xml version="1.0" ?>
<robot name="my_cabinet">
	<link name="world"/>
	<joint name="virtual_joint" type="fixed">
		<parent link="world"/>
		<child link="base_cabinet_link"/>
		<origin xyz="0.0 0.0 0.0" rpy="0.0 0.0 0.0"/>
	</joint>
	<link name="base_cabinet_link">
		<visual>
			<origin xyz="0.0 -0.0025 -0.17204618002771324" rpy="0.0 0.0 0.0"/>
			<geometry>
				<box size="0.3 0.32010508906761626 0.018"/>
			</geometry>
		</visual>
		<collision name="base_cabinet_link_collision_0">
			<origin xyz="0.0 -0.0025 -0.17204618002771324" rpy="0.0 0.0 0.0"/>
			<geometry>
				<box size="0.3 0.32010508906761626 0.018"/>
			</geometry>
		</collision>
		<visual>
			<origin xyz="0.0 0.14855254453380815 0.0" rpy="0.0 0.0 0.0"/>
			<geometry>
				<box size="0.3 0.018 0.3620923600554265"/>
			</geometry>
		</visual>
		<collision name="base_cabinet_link_collision_1">
			<origin xyz="0.0 0.14855254453380815 0.0" rpy="0.0 0.0 0.0"/>
			<geometry>
				<box size="0.3 0.018 0.3620923600554265"/>
			</geometry>
		</collision>
		<visual>
			<origin xyz="0.0 -0.15355254453380815 0.0" rpy="0.0 0.0 0.0"/>
			<geometry>
				<box size="0.3 0.018 0.3620923600554265"/>
			</geometry>
		</visual>
		<collision name="base_cabinet_link_collision_2">
			<origin xyz="0.0 -0.15355254453380815 0.0" rpy="0.0 0.0 0.0"/>
			<geometry>
				<box size="0.3 0.018 0.3620923600554265"/>
			</geometry>
		</collision>
		<visual>
			<origin xyz="0.0 -0.0025 0.17204618002771324" rpy="0.0 0.0 0.0"/>
			<geometry>
				<box size="0.3 0.32010508906761626 0.018"/>
			</geometry>
		</visual>
		<collision name="base_cabinet_link_collision_3">
			<origin xyz="0.0 -0.0025 0.17204618002771324" rpy="0.0 0.0 0.0"/>
			<geometry>
				<box size="0.3 0.32010508906761626 0.018"/>
			</geometry>
		</collision>
		<visual>
			<origin xyz="-0.141 -0.0025 0.0" rpy="0.0 0.0 0.0"/>
			<geometry>
				<box size="0.018 0.32010508906761626 0.3620923600554265"/>
			</geometry>
		</visual>
		<collision name="base_cabinet_link_collision_4">
			<origin xyz="-0.141 -0.0025 0.0" rpy="0.0 0.0 0.0"/>
			<geometry>
				<box size="0.018 0.32010508906761626 0.3620923600554265"/>
			</geometry>
		</collision>
		<inertial>
			<mass value="0.200000"/>
			<inertia ixx="0.003893" ixy="0.0" ixz="0.0" iyy="0.003685" iyz="0.0" izz="0.003208"/>
		</inertial>
	</link>
	<link name="door_link">
		<visual>
			<origin xyz="0.0 -0.13455254453380813 0.0"/>
			<geometry>
				<box size="0.018 0.26910508906761627 0.31609236005542646"/>
			</geometry>
		</visual>
		<collision name="door_link_collision">
			<origin xyz="0.0 -0.13455254453380813 0.0"/>
			<geometry>
				<box size="0.018 0.26910508906761627 0.31609236005542646"/>
			</geometry>
		</collision>
		<inertial>
			<mass value="0.200000"/>
			<inertia ixx="0.002872" ixy="0.0" ixz="0.0" iyy="0.001671" iyz="0.0" izz="0.001212"/>
		</inertial>
	</link>
	<joint name="door_joint" type="revolute">
		<origin xyz="0.141 -0.13455254453380813 0.0" rpy="0.000000 -0.000000 3.141593"/>
		<axis xyz="0 0 1"/>
		<parent link="base_cabinet_link"/>
		<child link="door_link"/>
		<limit effort="50" lower="-1.658062789394613" upper="0" velocity="10"/>
		<dynamics friction="3.5" damping="3.5"/>
	</joint>
	<link name="handle_link">
		<visual>
			<origin xyz="0.0 0.0 0.0" rpy="0.0 0.0 0.0"/>
			<geometry>
				<cylinder length="0.08" radius="0.005"/>
			</geometry>
		</visual>
		<collision name="handle_link_collision_0">
			<origin xyz="0.0 0.0 0.0" rpy="0.0 0.0 0.0"/>
			<geometry>
				<cylinder length="0.08" radius="0.005"/>
			</geometry>
		</collision>
		<visual>
			<origin xyz="-0.01 0.0 0.02" rpy="0.0 1.5707963267948966 0.0"/>
			<geometry>
				<cylinder length="0.02" radius="0.003"/>
			</geometry>
		</visual>
		<collision name="handle_link_collision_1">
			<origin xyz="-0.01 0.0 0.02" rpy="0.0 1.5707963267948966 0.0"/>
			<geometry>
				<cylinder length="0.01" radius="0.003"/>
			</geometry>
		</collision>
		<visual>
			<origin xyz="-0.01 0.0 -0.02" rpy="0.0 1.5707963267948966 0.0"/>
			<geometry>
				<cylinder length="0.02" radius="0.003"/>
			</geometry>
		</visual>
		<collision name="handle_link_collision_2">
			<origin xyz="-0.01 0.0 -0.02" rpy="0.0 1.5707963267948966 0.0"/>
			<geometry>
				<cylinder length="0.02" radius="0.003"/>
			</geometry>
		</collision>
		<inertial>
			<mass value="0.050000"/>
			<inertia ixx="0.000027" ixy="0.0" ixz="0.0" iyy="0.000029" iyz="0.0" izz="0.000003"/>
		</inertial>
	</link>
	<joint name="handle_joint" type="fixed">
		<origin xyz="-0.028999999999999998 -0.21910508906761628 0.0" rpy="0.000000 -0.000000 3.141593"/>
		<parent link="door_link"/>
		<child link="handle_link"/>
	</joint>
	<gazebo reference="base_cabinet_link">
		<sensor name="main_sensor" type="contact">
			<selfCollide>true</selfCollide>
			<alwaysOn>true</alwaysOn>
			<updateRate>5.0</updateRate>
			<material>Gazebo/Red</material>
			<contact>
				<collision>base_cabinet_link_collision_0_collision</collision>
				<collision>base_cabinet_link_collision_1_collision</collision>
				<collision>base_cabinet_link_collision_2_collision</collision>
				<collision>base_cabinet_link_collision_3_collision</collision>
				<collision>base_cabinet_link_collision_4_collision</collision>
			</contact>
			<plugin name="gazebo_ros_bumper_controller" filename="libgazebo_ros_bumper.so">
				<bumperTopicName>/contact</bumperTopicName>
				<frameName>world</frameName>
			</plugin>
		</sensor>
	</gazebo>
	<gazebo reference="door_link">
		<sensor name="main_sensor" type="contact">
			<selfCollide>true</selfCollide>
			<alwaysOn>true</alwaysOn>
			<updateRate>5.0</updateRate>
			<material>Gazebo/Red</material>
			<contact>
				<collision>door_link_collision_collision</collision>
			</contact>
			<plugin name="gazebo_ros_bumper_controller" filename="libgazebo_ros_bumper.so">
				<bumperTopicName>/contact_door</bumperTopicName>
				<frameName>contact_door</frameName>
			</plugin>
		</sensor>
	</gazebo>
	<gazebo reference="door_link">
		<mu>3.0</mu>
		<mu2>3.0</mu2>
		<kp>10000000</kp>
		<kd>100</kd>
	</gazebo>
</robot>
