<?xml version="1.0" ?>
<robot name="my_cabinet">
	<link name="world"/>
	<joint name="virtual_joint" type="fixed">
		<parent link="world"/>
		<child link="base_cabinet_link"/>
		<origin xyz="0.0 0.0 0.0" rpy="0.0 0.0 0.0"/>
	</joint>
	<link name="base_cabinet_link">
		<visual>
			<origin xyz="0.0 0.0 -0.255" rpy="0.0 0.0 0.0"/>
			<geometry>
				<box size="0.3 0.442 0.004"/>
			</geometry>
		</visual>
		<collision name="base_cabinet_link_collision_0">
			<origin xyz="0.0 0.0 -0.255" rpy="0.0 0.0 0.0"/>
			<geometry>
				<box size="0.3 0.442 0.004"/>
			</geometry>
		</collision>
		<visual>
			<origin xyz="0.0 0.212 0.007" rpy="0.0 0.0 0.0"/>
			<geometry>
				<box size="0.3 0.018 0.528"/>
			</geometry>
		</visual>
		<collision name="base_cabinet_link_collision_1">
			<origin xyz="0.0 0.212 0.007" rpy="0.0 0.0 0.0"/>
			<geometry>
				<box size="0.3 0.018 0.528"/>
			</geometry>
		</collision>
		<visual>
			<origin xyz="0.0 -0.212 0.007" rpy="0.0 0.0 0.0"/>
			<geometry>
				<box size="0.3 0.018 0.528"/>
			</geometry>
		</visual>
		<collision name="base_cabinet_link_collision_2">
			<origin xyz="0.0 -0.212 0.007" rpy="0.0 0.0 0.0"/>
			<geometry>
				<box size="0.3 0.018 0.528"/>
			</geometry>
		</collision>
		<visual>
			<origin xyz="0.0 0.0 0.262" rpy="0.0 0.0 0.0"/>
			<geometry>
				<box size="0.3 0.442 0.018"/>
			</geometry>
		</visual>
		<collision name="base_cabinet_link_collision_3">
			<origin xyz="0.0 0.0 0.262" rpy="0.0 0.0 0.0"/>
			<geometry>
				<box size="0.3 0.442 0.018"/>
			</geometry>
		</collision>
		<visual>
			<origin xyz="-0.141 0.0 0.007" rpy="0.0 0.0 0.0"/>
			<geometry>
				<box size="0.018 0.442 0.528"/>
			</geometry>
		</visual>
		<collision name="base_cabinet_link_collision_4">
			<origin xyz="-0.141 0.0 0.007" rpy="0.0 0.0 0.0"/>
			<geometry>
				<box size="0.018 0.442 0.528"/>
			</geometry>
		</collision>
		<inertial>
			<mass value="0.200000"/>
			<inertia ixx="0.007902" ixy="0.0" ixz="0.0" iyy="0.006146" iyz="0.0" izz="0.004756"/>
		</inertial>
	</link>
	<link name="door_link">
		<visual>
			<origin xyz="0.0 -0.188 0.0"/>
			<geometry>
				<box size="0.018 0.396 0.496"/>
			</geometry>
		</visual>
		<collision name="door_link_collision">
			<origin xyz="0.0 -0.188 0.0"/>
			<geometry>
				<box size="0.018 0.396 0.496"/>
			</geometry>
		</collision>
		<inertial>
			<mass value="0.200000"/>
			<inertia ixx="0.006714" ixy="0.0" ixz="0.0" iyy="0.004106" iyz="0.0" izz="0.002619"/>
		</inertial>
	</link>
	<joint name="door_joint" type="revolute">
		<origin xyz="0.141 -0.188 0.0" rpy="0.000000 -0.000000 3.141593"/>
		<axis xyz="0 0 1"/>
		<parent link="base_cabinet_link"/>
		<child link="door_link"/>
		<limit effort="50" lower="-1.5707963267948966" upper="0" velocity="10"/>
		<dynamics friction="1.0"/>
	</joint>
	<gazebo reference="base_cabinet_link">
		<sensor name="main_sensor" type="contact">
			<selfCollide>true</selfCollide>
			<alwaysOn>true</alwaysOn>
			<updateRate>5.0</updateRate>
			<material>Gazebo/Red</material>
			<contact>
				<collision>base_cabinet_link_collision_0_collision</collision>
				<collision>base_cabinet_link_collision_1_collision</collision>
				<collision>base_cabinet_link_collision_2_collision</collision>
				<collision>base_cabinet_link_collision_3_collision</collision>
				<collision>base_cabinet_link_collision_4_collision</collision>
			</contact>
			<plugin name="gazebo_ros_bumper_controller" filename="libgazebo_ros_bumper.so">
				<bumperTopicName>/contact</bumperTopicName>
				<frameName>world</frameName>
			</plugin>
		</sensor>
	</gazebo>
	<gazebo reference="door_link">
		<sensor name="main_sensor" type="contact">
			<selfCollide>true</selfCollide>
			<alwaysOn>true</alwaysOn>
			<updateRate>5.0</updateRate>
			<material>Gazebo/Red</material>
			<contact>
				<collision>door_link_collision_collision</collision>
			</contact>
			<plugin name="gazebo_ros_bumper_controller" filename="libgazebo_ros_bumper.so">
				<bumperTopicName>/contact_door</bumperTopicName>
				<frameName>contact_door</frameName>
			</plugin>
		</sensor>
	</gazebo>
</robot>
