<?xml version="1.0" ?>
<robot name="my_cabinet">
	<link name="world"/>
	<joint name="virtual_joint" type="fixed">
		<parent link="world"/>
		<child link="base_cabinet_link"/>
		<origin xyz="0.0 0.0 0.0" rpy="0.0 0.0 0.0"/>
	</joint>
	<link name="base_cabinet_link">
		<visual>
			<origin xyz="0.0 0.0 -0.31606009165485155" rpy="0.0 0.0 0.0"/>
			<geometry>
				<box size="0.4 0.29617563489536053 0.004"/>
			</geometry>
		</visual>
		<collision name="base_cabinet_link_collision_0">
			<origin xyz="0.0 0.0 -0.31606009165485155" rpy="0.0 0.0 0.0"/>
			<geometry>
				<box size="0.4 0.29617563489536053 0.004"/>
			</geometry>
		</collision>
		<visual>
			<origin xyz="0.0 0.13908781744768026 0.007" rpy="0.0 0.0 0.0"/>
			<geometry>
				<box size="0.4 0.018 0.6501201833097031"/>
			</geometry>
		</visual>
		<collision name="base_cabinet_link_collision_1">
			<origin xyz="0.0 0.13908781744768026 0.007" rpy="0.0 0.0 0.0"/>
			<geometry>
				<box size="0.4 0.018 0.6501201833097031"/>
			</geometry>
		</collision>
		<visual>
			<origin xyz="0.0 -0.13908781744768026 0.007" rpy="0.0 0.0 0.0"/>
			<geometry>
				<box size="0.4 0.018 0.6501201833097031"/>
			</geometry>
		</visual>
		<collision name="base_cabinet_link_collision_2">
			<origin xyz="0.0 -0.13908781744768026 0.007" rpy="0.0 0.0 0.0"/>
			<geometry>
				<box size="0.4 0.018 0.6501201833097031"/>
			</geometry>
		</collision>
		<visual>
			<origin xyz="0.0 0.0 0.32306009165485156" rpy="0.0 0.0 0.0"/>
			<geometry>
				<box size="0.4 0.29617563489536053 0.018"/>
			</geometry>
		</visual>
		<collision name="base_cabinet_link_collision_3">
			<origin xyz="0.0 0.0 0.32306009165485156" rpy="0.0 0.0 0.0"/>
			<geometry>
				<box size="0.4 0.29617563489536053 0.018"/>
			</geometry>
		</collision>
		<visual>
			<origin xyz="-0.191 0.0 0.007" rpy="0.0 0.0 0.0"/>
			<geometry>
				<box size="0.018 0.29617563489536053 0.6501201833097031"/>
			</geometry>
		</visual>
		<collision name="base_cabinet_link_collision_4">
			<origin xyz="-0.191 0.0 0.007" rpy="0.0 0.0 0.0"/>
			<geometry>
				<box size="0.018 0.29617563489536053 0.6501201833097031"/>
			</geometry>
		</collision>
		<inertial>
			<mass value="0.200000"/>
			<inertia ixx="0.008506" ixy="0.0" ixz="0.0" iyy="0.009711" iyz="0.0" izz="0.004129"/>
		</inertial>
	</link>
	<link name="door_link">
		<visual>
			<origin xyz="0.0 0.11508781744768028 0.0"/>
			<geometry>
				<box size="0.018 0.25017563489536054 0.6181201833097031"/>
			</geometry>
		</visual>
		<collision name="door_link_collision">
			<origin xyz="0.0 0.11508781744768028 0.0"/>
			<geometry>
				<box size="0.018 0.25017563489536054 0.6181201833097031"/>
			</geometry>
		</collision>
		<inertial>
			<mass value="0.200000"/>
			<inertia ixx="0.007411" ixy="0.0" ixz="0.0" iyy="0.006373" iyz="0.0" izz="0.001049"/>
		</inertial>
	</link>
	<joint name="door_joint" type="revolute">
		<origin xyz="0.191 -0.11508781744768028 0" rpy="0 0 0"/>
		<axis xyz="0 0 1"/>
		<parent link="base_cabinet_link"/>
		<child link="door_link"/>
		<limit effort="50" lower="0" upper="-1.5707963267948966" velocity="10"/>
		<dynamics friction="1.0"/>
	</joint>
	<gazebo reference="base_cabinet_link">
		<sensor name="main_sensor" type="contact">
			<selfCollide>true</selfCollide>
			<alwaysOn>true</alwaysOn>
			<updateRate>5.0</updateRate>
			<material>Gazebo/Red</material>
			<contact>
				<collision>base_cabinet_link_collision_0_collision</collision>
				<collision>base_cabinet_link_collision_1_collision</collision>
				<collision>base_cabinet_link_collision_2_collision</collision>
				<collision>base_cabinet_link_collision_3_collision</collision>
				<collision>base_cabinet_link_collision_4_collision</collision>
			</contact>
			<plugin name="gazebo_ros_bumper_controller" filename="libgazebo_ros_bumper.so">
				<bumperTopicName>/contact</bumperTopicName>
				<frameName>world</frameName>
			</plugin>
		</sensor>
	</gazebo>
	<gazebo reference="door_link">
		<sensor name="main_sensor" type="contact">
			<selfCollide>true</selfCollide>
			<alwaysOn>true</alwaysOn>
			<updateRate>5.0</updateRate>
			<material>Gazebo/Red</material>
			<contact>
				<collision>door_link_collision_collision</collision>
			</contact>
			<plugin name="gazebo_ros_bumper_controller" filename="libgazebo_ros_bumper.so">
				<bumperTopicName>/contact_door</bumperTopicName>
				<frameName>contact_door</frameName>
			</plugin>
		</sensor>
	</gazebo>
</robot>
