<?xml version="1.0" ?>
<robot name="my_cabinet">
	<link name="world"/>
	<joint name="virtual_joint" type="fixed">
		<parent link="world"/>
		<child link="base_cabinet_link"/>
		<origin xyz="0.0 0.0 0.0" rpy="0.0 0.0 0.0"/>
	</joint>
	<link name="base_cabinet_link">
		<visual>
			<origin xyz="0.0 0.0 -0.264" rpy="0.0 0.0 0.0"/>
			<geometry>
				<box size="0.4 0.346 0.018"/>
			</geometry>
		</visual>
		<collision>
			<origin xyz="0.0 0.0 -0.264" rpy="0.0 0.0 0.0"/>
			<geometry>
				<box size="0.4 0.346 0.018"/>
			</geometry>
		</collision>
		<visual>
			<origin xyz="0.0 0.16399999999999998 0.0" rpy="0.0 0.0 0.0"/>
			<geometry>
				<box size="0.4 0.018 0.546"/>
			</geometry>
		</visual>
		<collision>
			<origin xyz="0.0 0.16399999999999998 0.0" rpy="0.0 0.0 0.0"/>
			<geometry>
				<box size="0.4 0.018 0.546"/>
			</geometry>
		</collision>
		<visual>
			<origin xyz="0.0 -0.16399999999999998 0.0" rpy="0.0 0.0 0.0"/>
			<geometry>
				<box size="0.4 0.018 0.546"/>
			</geometry>
		</visual>
		<collision>
			<origin xyz="0.0 -0.16399999999999998 0.0" rpy="0.0 0.0 0.0"/>
			<geometry>
				<box size="0.4 0.018 0.546"/>
			</geometry>
		</collision>
		<visual>
			<origin xyz="0.0 0.0 0.264" rpy="0.0 0.0 0.0"/>
			<geometry>
				<box size="0.4 0.346 0.018"/>
			</geometry>
		</visual>
		<collision>
			<origin xyz="0.0 0.0 0.264" rpy="0.0 0.0 0.0"/>
			<geometry>
				<box size="0.4 0.346 0.018"/>
			</geometry>
		</collision>
		<visual>
			<origin xyz="-0.191 0.0 0.0" rpy="0.0 0.0 0.0"/>
			<geometry>
				<box size="0.018 0.346 0.546"/>
			</geometry>
		</visual>
		<collision>
			<origin xyz="-0.191 0.0 0.0" rpy="0.0 0.0 0.0"/>
			<geometry>
				<box size="0.018 0.346 0.546"/>
			</geometry>
		</collision>
		<inertial>
			<mass value="0.200000"/>
			<inertia ixx="0.006964" ixy="0.0" ixz="0.0" iyy="0.007635" iyz="0.0" izz="0.004662"/>
		</inertial>
	</link>
	<link name="door_link">
		<visual>
			<origin xyz="0.0 -0.13999999999999999 0.0"/>
			<geometry>
				<box size="0.018 0.3 0.5"/>
			</geometry>
		</visual>
		<collision>
			<origin xyz="0.0 -0.13999999999999999 0.0"/>
			<geometry>
				<box size="0.018 0.3 0.5"/>
			</geometry>
		</collision>
		<inertial>
			<mass value="0.200000"/>
			<inertia ixx="0.005667" ixy="0.0" ixz="0.0" iyy="0.004172" iyz="0.0" izz="0.001505"/>
		</inertial>
	</link>
	<joint name="door_joint" type="revolute">
		<origin xyz="0.191 0.13999999999999999 0" rpy="0 0 0"/>
		<axis xyz="0 0 1"/>
		<parent link="base_cabinet_link"/>
		<child link="door_link"/>
		<limit effort="50" lower="0" upper="1.5707963267948966" velocity="10"/>
		<dynamics friction="1.0"/>
	</joint>
	<gazebo reference="my_cabinet">
		<material>Gazebo/Blue</material>
	</gazebo>
</robot>
